<?xml version="1.0"?>
<robot name="carrot_robot">
  <!-- สี -->
  <material name="orange">
    <color rgba="1.0 0.5 0.0 1.0"/>
  </material>
  <material name="black">
    <color rgba="0.0 0.0 0.0 1.0"/>
  </material>
  <material name="gray">
    <color rgba="0.5 0.5 0.5 1.0"/>
  </material>
  <material name="blue">
    <color rgba="0.0 0.0 1.0 1.0"/>
  </material>
  
  <!-- Base footprint - จุดสัมผัสพื้น (จำเป็นสำหรับ Nav2) -->
  <link name="base_footprint"/>
  
  <!-- ฐานหุ่นยนต์ - กล่องสี่เหลี่ยม กว้าง/ยาว 15.9 cm สูง 8.1 cm -->
  <link name="base_link">
    <visual>
      <geometry>
        <box size="0.159 0.159 0.081"/>
      </geometry>
      <material name="orange"/>
      <origin xyz="0 0 0.013" rpy="0 0 0"/>
    </visual>
    <collision>
      <geometry>
        <box size="0.159 0.159 0.081"/>
      </geometry>
      <origin xyz="0 0 0.013" rpy="0 0 0"/>
    </collision>
  </link>
  
  <!-- ตัวบ่งชี้ด้านหน้าของหุ่นยนต์ -->
  <link name="front_indicator">
    <visual>
      <geometry>
        <box size="0.02 0.02 0.02"/>
      </geometry>
      <material name="blue"/>
    </visual>
  </link>
  
  <!-- ล้อซ้าย - รัศมี 2.15 cm -->
  <link name="left_wheel">
    <visual>
      <geometry>
        <cylinder length="0.02" radius="0.0215"/>
      </geometry>
      <material name="black"/>
      <origin xyz="0 0 0" rpy="1.5707 0 0"/>
    </visual>
    <collision>
      <geometry>
        <cylinder length="0.02" radius="0.0215"/>
      </geometry>
      <origin xyz="0 0 0" rpy="1.5707 0 0"/>
    </collision>
  </link>
  
  <!-- ล้อขวา - รัศมี 2.15 cm -->
  <link name="right_wheel">
    <visual>
      <geometry>
        <cylinder length="0.02" radius="0.0215"/>
      </geometry>
      <material name="black"/>
      <origin xyz="0 0 0" rpy="1.5707 0 0"/>
    </visual>
    <collision>
      <geometry>
        <cylinder length="0.02" radius="0.0215"/>
      </geometry>
      <origin xyz="0 0 0" rpy="1.5707 0 0"/>
    </collision>
  </link>
  
  <!-- เซนเซอร์ LIDAR - เส้นผ่านศูนย์กลาง 7 cm สูง 2.5 cm -->
  <link name="lidar">
    <visual>
      <geometry>
        <cylinder length="0.025" radius="0.035"/>
      </geometry>
      <material name="gray"/>
    </visual>
    <collision>
      <geometry>
        <cylinder length="0.025" radius="0.035"/>
      </geometry>
    </collision>
  </link>
  
  <!-- เฟรม laser (จำเป็นสำหรับการแสกนของ rplidar) -->
  <link name="laser"/>
  
  <!-- กำหนดจุดเชื่อมต่อระหว่างชิ้นส่วน -->
  <!-- base_footprint ไป base_link -->
  <joint name="base_footprint_joint" type="fixed">
    <parent link="base_footprint"/>
    <child link="base_link"/>
    <!-- ตำแหน่ง z = ครึ่งความสูง + รัศมีล้อ (จุด base_link อยู่ที่กึ่งกลาง) -->
    <origin xyz="0 0 0.039" rpy="0 0 0"/>
  </joint>
  
  <!-- ตัวบ่งชี้ด้านหน้า - วางไว้ด้านหน้าของหุ่นยนต์ (แกน X เป็นด้านหน้า) -->
  <joint name="front_indicator_joint" type="fixed">
    <parent link="base_link"/>
    <child link="front_indicator"/>
    <origin xyz="0.0795 0 0.0" rpy="0 0 0"/>
  </joint>
  
  <!-- ล้อซ้าย - ระยะห่างระหว่างล้อจากกึ่งกลาง 5.85 cm -->
  <joint name="left_wheel_joint" type="continuous">
    <parent link="base_link"/>
    <child link="left_wheel"/>
    <!-- ตำแหน่ง x=0 (กึ่งกลาง), y=ระยะห่างจากกึ่งกลาง 4.65 cm (9.3/2), z=รัศมีล้อ-ครึ่งความสูงของฐาน -->
    <origin xyz="0 0.0585 -0.0135" rpy="0 0 0"/>
    <axis xyz="0 1 0"/>
  </joint>
  
  <!-- ล้อขวา - ระยะห่างระหว่างล้อจากกึ่งกลาง 5.85 cm -->
  <joint name="right_wheel_joint" type="continuous">
    <parent link="base_link"/>
    <child link="right_wheel"/>
    <!-- ตำแหน่ง x=0 (กึ่งกลาง), y=-ระยะห่างจากกึ่งกลาง -4.65 cm (-9.3/2), z=รัศมีล้อ-ครึ่งความสูงของฐาน -->
    <origin xyz="0 -0.0585 -0.0135" rpy="0 0 0"/>
    <axis xyz="0 1 0"/>
  </joint>
  
  <!-- LIDAR - ตรงกลางและสูงจากฐาน 10.9 cm -->
  <joint name="lidar_joint" type="fixed">
    <parent link="base_link"/>
    <child link="lidar"/>
    <!-- z = ครึ่งความสูงของฐาน + ความสูงที่ LIDAR ยกจากฐาน + ครึ่งความสูงของ LIDAR -->
    <!-- xyz คือตำแหน่งของ LIDAR เทียบกับฐาน -->
    <!-- rpy คือมุมหมุนของ LIDAR เทียบกับฐาน r คือมุมหมุนรอบแกน X, p คือมุมหมุนรอบแกน Y, y คือมุมหมุนรอบแกน Z -->
    <!-- มุมเป็นหน่วยเรเดียน 45 องศา มีค่าประมาณ 0.7854 -->
    <origin xyz="0 0 0.109" rpy="0 0 3.1416"/>
  </joint>
  
  <!-- Laser frame เชื่อมกับ LIDAR -->
  <joint name="lidar_to_laser_joint" type="fixed">
    <parent link="lidar"/>
    <child link="laser"/>
    <origin xyz="0 0 0" rpy="0 0 0"/>
  </joint>
</robot> 